I'm sorry, but an uncaught exception occurred.

While running game code:
  File "game/scripts/aventura.rpy", line 91, in script
    n 'Você continua, mas sente suas pálpebras pesando...'
Exception: Sayer 'n' is not defined.

-- Full Traceback ------------------------------------------------------------

Full traceback:
  File "game/scripts/aventura.rpy", line 91, in script
    n 'Você continua, mas sente suas pálpebras pesando...'
  File "C:\Users\alber\Downloads\renpy-6.99.14-sdk\renpy\ast.py", line 615, in execute
    who = eval_who(self.who, self.who_fast)
  File "C:\Users\alber\Downloads\renpy-6.99.14-sdk\renpy\ast.py", line 528, in eval_who
    raise Exception("Sayer '%s' is not defined." % who.encode("utf-8"))
Exception: Sayer 'n' is not defined.

Windows-8-6.2.9200
Ren'Py 6.99.14.3135
vngamux 1.0
